<?xml version="1.0" encoding="UTF-8"?>
<testng-results skipped="0" failed="3" ignored="0" total="5" passed="2">
  <reporter-output>
  </reporter-output>
  <suite name="DataDrivenTestCases" duration-ms="149195" started-at="2023-08-09T11:55:30 IST" finished-at="2023-08-09T11:57:59 IST">
    <groups>
    </groups>
    <test name="BankingTest1" duration-ms="149195" started-at="2023-08-09T11:55:30 IST" finished-at="2023-08-09T11:57:59 IST">
      <class name="TestCases.DATLoginTest">
        <test-method status="PASS" signature="setup()[pri:0, instance:TestCases.DATLoginTest@16022d9d]" name="setup" is-config="true" duration-ms="8646" started-at="2023-08-09T11:55:30 IST" finished-at="2023-08-09T11:55:39 IST">
          <reporter-output>
          </reporter-output>
        </test-method> <!-- setup -->
        <test-method status="PASS" signature="loginDOt(java.lang.String,java.lang.String)[pri:0, instance:TestCases.DATLoginTest@16022d9d]" name="loginDOt" duration-ms="44804" started-at="2023-08-09T11:55:41 IST" data-provider="LoginData" finished-at="2023-08-09T11:56:26 IST">
          <params>
            <param index="0">
              <value>
                <![CDATA[pratik]]>
              </value>
            </param>
            <param index="1">
              <value>
                <![CDATA[pratik]]>
              </value>
            </param>
          </params>
          <reporter-output>
          </reporter-output>
        </test-method> <!-- loginDOt -->
        <test-method status="FAIL" signature="loginDOt(java.lang.String,java.lang.String)[pri:0, instance:TestCases.DATLoginTest@16022d9d]" name="loginDOt" duration-ms="21580" started-at="2023-08-09T11:56:26 IST" data-provider="LoginData" finished-at="2023-08-09T11:56:48 IST">
          <params>
            <param index="0">
              <value>
                <![CDATA[mn518773]]>
              </value>
            </param>
            <param index="1">
              <value>
                <![CDATA[tUvararcbc]]>
              </value>
            </param>
          </params>
          <exception class="java.lang.AssertionError">
            <message>
              <![CDATA[expected [true] but found [false]]]>
            </message>
            <full-stacktrace>
              <![CDATA[java.lang.AssertionError: expected [true] but found [false]
at org.testng.Assert.fail(Assert.java:99)
at org.testng.Assert.failNotEquals(Assert.java:1037)
at org.testng.Assert.assertTrue(Assert.java:45)
at org.testng.Assert.assertTrue(Assert.java:55)
at TestCases.DATLoginTest.loginDOt(Unknown Source)
at sun.reflect.NativeMethodAccessorImpl.invoke0(Native Method)
at sun.reflect.NativeMethodAccessorImpl.invoke(Unknown Source)
at sun.reflect.DelegatingMethodAccessorImpl.invoke(Unknown Source)
at java.lang.reflect.Method.invoke(Unknown Source)
at org.testng.internal.MethodInvocationHelper.invokeMethod(MethodInvocationHelper.java:133)
at org.testng.internal.TestInvoker.invokeMethod(TestInvoker.java:598)
at org.testng.internal.TestInvoker.invokeTestMethod(TestInvoker.java:173)
at org.testng.internal.MethodRunner.runInSequence(MethodRunner.java:46)
at org.testng.internal.TestInvoker$MethodInvocationAgent.invoke(TestInvoker.java:824)
at org.testng.internal.TestInvoker.invokeTestMethods(TestInvoker.java:146)
at org.testng.internal.TestMethodWorker.invokeTestMethods(TestMethodWorker.java:146)
at org.testng.internal.TestMethodWorker.run(TestMethodWorker.java:128)
at java.util.ArrayList.forEach(Unknown Source)
at org.testng.TestRunner.privateRun(TestRunner.java:794)
at org.testng.TestRunner.run(TestRunner.java:596)
at org.testng.SuiteRunner.runTest(SuiteRunner.java:377)
at org.testng.SuiteRunner.runSequentially(SuiteRunner.java:371)
at org.testng.SuiteRunner.privateRun(SuiteRunner.java:332)
at org.testng.SuiteRunner.run(SuiteRunner.java:276)
at org.testng.SuiteRunnerWorker.runSuite(SuiteRunnerWorker.java:53)
at org.testng.SuiteRunnerWorker.run(SuiteRunnerWorker.java:96)
at org.testng.TestNG.runSuitesSequentially(TestNG.java:1212)
at org.testng.TestNG.runSuitesLocally(TestNG.java:1134)
at org.testng.TestNG.runSuites(TestNG.java:1063)
at org.testng.TestNG.run(TestNG.java:1031)
at org.testng.remote.AbstractRemoteTestNG.run(AbstractRemoteTestNG.java:115)
at org.testng.remote.RemoteTestNG.initAndRun(RemoteTestNG.java:251)
at org.testng.remote.RemoteTestNG.main(RemoteTestNG.java:77)
]]>
            </full-stacktrace>
          </exception> <!-- java.lang.AssertionError -->
          <reporter-output>
          </reporter-output>
        </test-method> <!-- loginDOt -->
        <test-method status="FAIL" signature="loginDOt(java.lang.String,java.lang.String)[pri:0, instance:TestCases.DATLoginTest@16022d9d]" name="loginDOt" duration-ms="21397" started-at="2023-08-09T11:56:48 IST" data-provider="LoginData" finished-at="2023-08-09T11:57:09 IST">
          <params>
            <param index="0">
              <value>
                <![CDATA[mngr518773]]>
              </value>
            </param>
            <param index="1">
              <value>
                <![CDATA[tUvarar]]>
              </value>
            </param>
          </params>
          <exception class="java.lang.AssertionError">
            <message>
              <![CDATA[expected [true] but found [false]]]>
            </message>
            <full-stacktrace>
              <![CDATA[java.lang.AssertionError: expected [true] but found [false]
at org.testng.Assert.fail(Assert.java:99)
at org.testng.Assert.failNotEquals(Assert.java:1037)
at org.testng.Assert.assertTrue(Assert.java:45)
at org.testng.Assert.assertTrue(Assert.java:55)
at TestCases.DATLoginTest.loginDOt(Unknown Source)
at sun.reflect.NativeMethodAccessorImpl.invoke0(Native Method)
at sun.reflect.NativeMethodAccessorImpl.invoke(Unknown Source)
at sun.reflect.DelegatingMethodAccessorImpl.invoke(Unknown Source)
at java.lang.reflect.Method.invoke(Unknown Source)
at org.testng.internal.MethodInvocationHelper.invokeMethod(MethodInvocationHelper.java:133)
at org.testng.internal.TestInvoker.invokeMethod(TestInvoker.java:598)
at org.testng.internal.TestInvoker.invokeTestMethod(TestInvoker.java:173)
at org.testng.internal.MethodRunner.runInSequence(MethodRunner.java:46)
at org.testng.internal.TestInvoker$MethodInvocationAgent.invoke(TestInvoker.java:824)
at org.testng.internal.TestInvoker.invokeTestMethods(TestInvoker.java:146)
at org.testng.internal.TestMethodWorker.invokeTestMethods(TestMethodWorker.java:146)
at org.testng.internal.TestMethodWorker.run(TestMethodWorker.java:128)
at java.util.ArrayList.forEach(Unknown Source)
at org.testng.TestRunner.privateRun(TestRunner.java:794)
at org.testng.TestRunner.run(TestRunner.java:596)
at org.testng.SuiteRunner.runTest(SuiteRunner.java:377)
at org.testng.SuiteRunner.runSequentially(SuiteRunner.java:371)
at org.testng.SuiteRunner.privateRun(SuiteRunner.java:332)
at org.testng.SuiteRunner.run(SuiteRunner.java:276)
at org.testng.SuiteRunnerWorker.runSuite(SuiteRunnerWorker.java:53)
at org.testng.SuiteRunnerWorker.run(SuiteRunnerWorker.java:96)
at org.testng.TestNG.runSuitesSequentially(TestNG.java:1212)
at org.testng.TestNG.runSuitesLocally(TestNG.java:1134)
at org.testng.TestNG.runSuites(TestNG.java:1063)
at org.testng.TestNG.run(TestNG.java:1031)
at org.testng.remote.AbstractRemoteTestNG.run(AbstractRemoteTestNG.java:115)
at org.testng.remote.RemoteTestNG.initAndRun(RemoteTestNG.java:251)
at org.testng.remote.RemoteTestNG.main(RemoteTestNG.java:77)
]]>
            </full-stacktrace>
          </exception> <!-- java.lang.AssertionError -->
          <reporter-output>
          </reporter-output>
        </test-method> <!-- loginDOt -->
        <test-method status="PASS" signature="loginDOt(java.lang.String,java.lang.String)[pri:0, instance:TestCases.DATLoginTest@16022d9d]" name="loginDOt" duration-ms="23074" started-at="2023-08-09T11:57:09 IST" data-provider="LoginData" finished-at="2023-08-09T11:57:32 IST">
          <params>
            <param index="0">
              <value>
                <![CDATA[pratik]]>
              </value>
            </param>
            <param index="1">
              <value>
                <![CDATA[pratik]]>
              </value>
            </param>
          </params>
          <reporter-output>
          </reporter-output>
        </test-method> <!-- loginDOt -->
        <test-method status="FAIL" signature="loginDOt(java.lang.String,java.lang.String)[pri:0, instance:TestCases.DATLoginTest@16022d9d]" name="loginDOt" duration-ms="25652" started-at="2023-08-09T11:57:32 IST" data-provider="LoginData" finished-at="2023-08-09T11:57:58 IST">
          <params>
            <param index="0">
              <value>
                <![CDATA[mngrhrtyhrt518773]]>
              </value>
            </param>
            <param index="1">
              <value>
                <![CDATA[tUvarfhfghar]]>
              </value>
            </param>
          </params>
          <exception class="java.lang.AssertionError">
            <message>
              <![CDATA[expected [true] but found [false]]]>
            </message>
            <full-stacktrace>
              <![CDATA[java.lang.AssertionError: expected [true] but found [false]
at org.testng.Assert.fail(Assert.java:99)
at org.testng.Assert.failNotEquals(Assert.java:1037)
at org.testng.Assert.assertTrue(Assert.java:45)
at org.testng.Assert.assertTrue(Assert.java:55)
at TestCases.DATLoginTest.loginDOt(Unknown Source)
at sun.reflect.NativeMethodAccessorImpl.invoke0(Native Method)
at sun.reflect.NativeMethodAccessorImpl.invoke(Unknown Source)
at sun.reflect.DelegatingMethodAccessorImpl.invoke(Unknown Source)
at java.lang.reflect.Method.invoke(Unknown Source)
at org.testng.internal.MethodInvocationHelper.invokeMethod(MethodInvocationHelper.java:133)
at org.testng.internal.TestInvoker.invokeMethod(TestInvoker.java:598)
at org.testng.internal.TestInvoker.invokeTestMethod(TestInvoker.java:173)
at org.testng.internal.MethodRunner.runInSequence(MethodRunner.java:46)
at org.testng.internal.TestInvoker$MethodInvocationAgent.invoke(TestInvoker.java:824)
at org.testng.internal.TestInvoker.invokeTestMethods(TestInvoker.java:146)
at org.testng.internal.TestMethodWorker.invokeTestMethods(TestMethodWorker.java:146)
at org.testng.internal.TestMethodWorker.run(TestMethodWorker.java:128)
at java.util.ArrayList.forEach(Unknown Source)
at org.testng.TestRunner.privateRun(TestRunner.java:794)
at org.testng.TestRunner.run(TestRunner.java:596)
at org.testng.SuiteRunner.runTest(SuiteRunner.java:377)
at org.testng.SuiteRunner.runSequentially(SuiteRunner.java:371)
at org.testng.SuiteRunner.privateRun(SuiteRunner.java:332)
at org.testng.SuiteRunner.run(SuiteRunner.java:276)
at org.testng.SuiteRunnerWorker.runSuite(SuiteRunnerWorker.java:53)
at org.testng.SuiteRunnerWorker.run(SuiteRunnerWorker.java:96)
at org.testng.TestNG.runSuitesSequentially(TestNG.java:1212)
at org.testng.TestNG.runSuitesLocally(TestNG.java:1134)
at org.testng.TestNG.runSuites(TestNG.java:1063)
at org.testng.TestNG.run(TestNG.java:1031)
at org.testng.remote.AbstractRemoteTestNG.run(AbstractRemoteTestNG.java:115)
at org.testng.remote.RemoteTestNG.initAndRun(RemoteTestNG.java:251)
at org.testng.remote.RemoteTestNG.main(RemoteTestNG.java:77)
]]>
            </full-stacktrace>
          </exception> <!-- java.lang.AssertionError -->
          <reporter-output>
          </reporter-output>
        </test-method> <!-- loginDOt -->
        <test-method status="PASS" signature="teardown()[pri:0, instance:TestCases.DATLoginTest@16022d9d]" name="teardown" is-config="true" duration-ms="1115" started-at="2023-08-09T11:57:58 IST" finished-at="2023-08-09T11:57:59 IST">
          <reporter-output>
          </reporter-output>
        </test-method> <!-- teardown -->
      </class> <!-- TestCases.DATLoginTest -->
    </test> <!-- BankingTest1 -->
  </suite> <!-- DataDrivenTestCases -->
</testng-results>
